Traceback (most recent call last):
  File "C:\Users\sashk\AppData\Local\Programs\Python\Python313\Lib\site-packages\jupyter_cache\executors\utils.py", line 58, in single_nb_execution
    executenb(
    ~~~~~~~~~^
        nb,
        ^^^
    ...<4 lines>...
        **kwargs,
        ^^^^^^^^^
    )
    ^
  File "C:\Users\sashk\AppData\Local\Programs\Python\Python313\Lib\site-packages\nbclient\client.py", line 1319, in execute
    return NotebookClient(nb=nb, resources=resources, km=km, **kwargs).execute()
           ~~~~~~~~~~~~~~~~~~~~~~~~~~~~~~~~~~~~~~~~~~~~~~~~~~~~~~~~~~~~~~~~~~~^^
  File "C:\Users\sashk\AppData\Local\Programs\Python\Python313\Lib\site-packages\jupyter_core\utils\__init__.py", line 165, in wrapped
    return loop.run_until_complete(inner)
           ~~~~~~~~~~~~~~~~~~~~~~~^^^^^^^
  File "C:\Users\sashk\AppData\Local\Programs\Python\Python313\Lib\asyncio\base_events.py", line 725, in run_until_complete
    return future.result()
           ~~~~~~~~~~~~~^^
  File "C:\Users\sashk\AppData\Local\Programs\Python\Python313\Lib\site-packages\nbclient\client.py", line 709, in async_execute
    await self.async_execute_cell(
        cell, index, execution_count=self.code_cells_executed + 1
    )
  File "C:\Users\sashk\AppData\Local\Programs\Python\Python313\Lib\site-packages\nbclient\client.py", line 1062, in async_execute_cell
    await self._check_raise_for_error(cell, cell_index, exec_reply)
  File "C:\Users\sashk\AppData\Local\Programs\Python\Python313\Lib\site-packages\nbclient\client.py", line 918, in _check_raise_for_error
    raise CellExecutionError.from_cell_and_msg(cell, exec_reply_content)
nbclient.exceptions.CellExecutionError: An error occurred while executing the following cell:
------------------
import pandas as pd
import numpy as np
import networkx as nx
import os

import stellargraph as sg
from stellargraph.mapper import FullBatchNodeGenerator
from stellargraph.layer import GCN

import tensorflow as tf
from tensorflow.keras import layers, optimizers, losses, metrics, Model
from sklearn import preprocessing, model_selection
from IPython.display import display, HTML
import matplotlib.pyplot as plt
%matplotlib inline
------------------


[1;31m---------------------------------------------------------------------------[0m
[1;31mModuleNotFoundError[0m                       Traceback (most recent call last)
Cell [1;32mIn[6], line 6[0m
[0;32m      3[0m [38;5;28;01mimport[39;00m [38;5;21;01mnetworkx[39;00m [38;5;28;01mas[39;00m [38;5;21;01mnx[39;00m
[0;32m      4[0m [38;5;28;01mimport[39;00m [38;5;21;01mos[39;00m
[1;32m----> 6[0m [38;5;28;01mimport[39;00m [38;5;21;01mstellargraph[39;00m [38;5;28;01mas[39;00m [38;5;21;01msg[39;00m
[0;32m      7[0m [38;5;28;01mfrom[39;00m [38;5;21;01mstellargraph[39;00m[38;5;21;01m.[39;00m[38;5;21;01mmapper[39;00m [38;5;28;01mimport[39;00m FullBatchNodeGenerator
[0;32m      8[0m [38;5;28;01mfrom[39;00m [38;5;21;01mstellargraph[39;00m[38;5;21;01m.[39;00m[38;5;21;01mlayer[39;00m [38;5;28;01mimport[39;00m GCN

[1;31mModuleNotFoundError[0m: No module named 'stellargraph'

